Workbook

Sheet Simples
B1: Início da Projeção | C1: =MONTH(C3) -> 11 | D1: =MONTH(D3) -> 12 | E1: =MONTH(E3) -> 1 | F1: =MONTH(F3) -> 2 | G1: =MONTH(G3) -> 3 | H1: =MONTH(H3) -> 4 | I1: =MONTH(I3) -> 5 | J1: =MONTH(J3) -> 6 | ... BM1: =MONTH(BM3) -> 1 | BO1: x
B2: 46054 | C2: =YEAR(C3) -> 2021 | D2: =YEAR(D3) -> 2021 | E2: =YEAR(E3) -> 2022 | F2: =YEAR(F3) -> 2022 | G2: =YEAR(G3) -> 2022 | H2: =YEAR(H3) -> 2022 | I2: =YEAR(I3) -> 2022 | J2: =YEAR(J3) -> 2022 | ... BM2: =YEAR(BM3) -> 2027 | BO2: x
C3: =EDATE(D3,-1) -> 44501 | D3: =EDATE(E3,-1) -> 44531 | E3: =EDATE(F3,-1) -> 44562 | F3: =EDATE(G3,-1) -> 44593 | G3: =EDATE(H3,-1) -> 44621 | H3: =EDATE(I3,-1) -> 44652 | I3: =EDATE(J3,-1) -> 44682 | J3: =EDATE(K3,-1) -> 44713 | ... BA3: =EDATE(BB3,-1) -> 46023 | BB3: =$B$2 -> 46054 | BC3: =EDATE(BB3,1) -> 46082 | BD3: =EDATE(BC3,1) -> 46113 | BE3: =EDATE(BD3,1) -> 46143 | BF3: =EDATE(BE3,1) -> 46174 | BG3: =EDATE(BF3,1) -> 46204 | BH3: =EDATE(BG3,1) -> 46235 | BI3: =EDATE(BH3,1) -> 46266 | BJ3: =EDATE(BI3,1) -> 46296 | ... BM3: =EDATE(BL3,1) -> 46388 | BO3: x
A4: x | B4: Dados coletados | BO4: x
BO5: x
B6: Receita Bruta do PA (RPA) - Competência | BB6: =IFERROR(AVERAGE(AP6:BA6),0) -> 0 | BC6: =BB6 -> 0 | BD6: =BC6 -> 0 | BE6: =BD6 -> 0 | BF6: =BE6 -> 0 | BG6: =BF6 -> 0 | BH6: =BG6 -> 0 | BI6: =BH6 -> 0 | BJ6: =BI6 -> 0 | ... BM6: =BL6 -> 0 | BO6: x
B7: Revenda - SEM ST - Substituto | BB7: =IFERROR(BB$6*BA15,"-") -> 0 | BC7: =IFERROR(BC$6*BB15,"-") -> 0 | BD7: =IFERROR(BD$6*BC15,"-") -> 0 | BE7: =IFERROR(BE$6*BD15,"-") -> 0 | BF7: =IFERROR(BF$6*BE15,"-") -> 0 | BG7: =IFERROR(BG$6*BF15,"-") -> 0 | BH7: =IFERROR(BH$6*BG15,"-") -> 0 | BI7: =IFERROR(BI$6*BH15,"-") -> 0 | ... BM7: =IFERROR(BM$6*BL15,"-") -> 0 | BO7: x
B8: Revenda - SEM ST - Isenta ICMS | BB8: =IFERROR(BB$6*BA16,"-") -> 0 | BC8: =IFERROR(BC$6*BB16,"-") -> 0 | BD8: =IFERROR(BD$6*BC16,"-") -> 0 | BE8: =IFERROR(BE$6*BD16,"-") -> 0 | BF8: =IFERROR(BF$6*BE16,"-") -> 0 | BG8: =IFERROR(BG$6*BF16,"-") -> 0 | BH8: =IFERROR(BH$6*BG16,"-") -> 0 | BI8: =IFERROR(BI$6*BH16,"-") -> 0 | ... BM8: =IFERROR(BM$6*BL16,"-") -> 0 | BO8: x
B9: Revenda - COM ST - Substituído | BB9: =IFERROR(BB$6*BA17,"-") -> 0 | BC9: =IFERROR(BC$6*BB17,"-") -> 0 | BD9: =IFERROR(BD$6*BC17,"-") -> 0 | BE9: =IFERROR(BE$6*BD17,"-") -> 0 | BF9: =IFERROR(BF$6*BE17,"-") -> 0 | BG9: =IFERROR(BG$6*BF17,"-") -> 0 | BH9: =IFERROR(BH$6*BG17,"-") -> 0 | BI9: =IFERROR(BI$6*BH17,"-") -> 0 | ... BM9: =IFERROR(BM$6*BL17,"-") -> 0 | BO9: x
B10: Revenda Monofásicos | BB10: =IFERROR(BB$6*BA18,"-") -> 0 | BC10: =IFERROR(BC$6*BB18,"-") -> 0 | BD10: =IFERROR(BD$6*BC18,"-") -> 0 | BE10: =IFERROR(BE$6*BD18,"-") -> 0 | BF10: =IFERROR(BF$6*BE18,"-") -> 0 | BG10: =IFERROR(BG$6*BF18,"-") -> 0 | BH10: =IFERROR(BH$6*BG18,"-") -> 0 | BI10: =IFERROR(BI$6*BH18,"-") -> 0 | ... BM10: =IFERROR(BM$6*BL18,"-") -> 0 | BO10: x
B11: Revenda Monofásicos + ST | BB11: =IFERROR(BB$6*BA19,"-") -> 0 | BC11: =IFERROR(BC$6*BB19,"-") -> 0 | BD11: =IFERROR(BD$6*BC19,"-") -> 0 | BE11: =IFERROR(BE$6*BD19,"-") -> 0 | BF11: =IFERROR(BF$6*BE19,"-") -> 0 | BG11: =IFERROR(BG$6*BF19,"-") -> 0 | BH11: =IFERROR(BH$6*BG19,"-") -> 0 | BI11: =IFERROR(BI$6*BH19,"-") -> 0 | ... BM11: =IFERROR(BM$6*BL19,"-") -> 0 | BO11: x
B12: Venda de mercadoria ind. - SEM ST - Substituto | BB12: =IFERROR(BB$6*BA20,"-") -> 0 | BC12: =IFERROR(BC$6*BB20,"-") -> 0 | BD12: =IFERROR(BD$6*BC20,"-") -> 0 | BE12: =IFERROR(BE$6*BD20,"-") -> 0 | BF12: =IFERROR(BF$6*BE20,"-") -> 0 | BG12: =IFERROR(BG$6*BF20,"-") -> 0 | BH12: =IFERROR(BH$6*BG20,"-") -> 0 | BI12: =IFERROR(BI$6*BH20,"-") -> 0 | ... BM12: =IFERROR(BM$6*BL20,"-") -> 0 | BO12: x
B13: Venda de mercadoria ind. - COM ST - Substituído | BB13: =IFERROR(BB$6*BA21,"-") -> 0 | BC13: =IFERROR(BC$6*BB21,"-") -> 0 | BD13: =IFERROR(BD$6*BC21,"-") -> 0 | BE13: =IFERROR(BE$6*BD21,"-") -> 0 | BF13: =IFERROR(BF$6*BE21,"-") -> 0 | BG13: =IFERROR(BG$6*BF21,"-") -> 0 | BH13: =IFERROR(BH$6*BG21,"-") -> 0 | BI13: =IFERROR(BI$6*BH21,"-") -> 0 | ... BM13: =IFERROR(BM$6*BL21,"-") -> 0 | BO13: x
B14: Serviço anexo 3 (R$) | BB14: =IFERROR(BB$6*BA22,"-") -> 0 | BC14: =IFERROR(BC$6*BB22,"-") -> 0 | BD14: =IFERROR(BD$6*BC22,"-") -> 0 | BE14: =IFERROR(BE$6*BD22,"-") -> 0 | BF14: =IFERROR(BF$6*BE22,"-") -> 0 | BG14: =IFERROR(BG$6*BF22,"-") -> 0 | BH14: =IFERROR(BH$6*BG22,"-") -> 0 | BI14: =IFERROR(BI$6*BH22,"-") -> 0 | ... BM14: =IFERROR(BM$6*BL22,"-") -> 0 | BO14: x
B15: ="Percentual (%) "&B7 -> Percentual (%) Revenda - SEM ST - Substituto | C15: =IFERROR(IF(C7/C$6=0,0,C7/C$6),0) -> 0 | D15: =IFERROR(IF(D7/D$6=0,0,D7/D$6),0) -> 0 | E15: =IFERROR(IF(E7/E$6=0,0,E7/E$6),0) -> 0 | F15: =IFERROR(IF(F7/F$6=0,0,F7/F$6),0) -> 0 | G15: =IFERROR(IF(G7/G$6=0,0,G7/G$6),0) -> 0 | H15: =IFERROR(IF(H7/H$6=0,0,H7/H$6),0) -> 0 | I15: =IFERROR(IF(I7/I$6=0,0,I7/I$6),0) -> 0 | J15: =IFERROR(IF(J7/J$6=0,0,J7/J$6),0) -> 0 | ... BM15: =IFERROR(IF(BM7/BM$6=0,0,BM7/BM$6),0) -> 0 | BO15: x
B16: ="Percentual (%) "&B8 -> Percentual (%) Revenda - SEM ST - Isenta ICMS | C16: =IFERROR(IF(C8/C$6=0,0,C8/C$6),0) -> 0 | D16: =IFERROR(IF(D8/D$6=0,0,D8/D$6),0) -> 0 | E16: =IFERROR(IF(E8/E$6=0,0,E8/E$6),0) -> 0 | F16: =IFERROR(IF(F8/F$6=0,0,F8/F$6),0) -> 0 | G16: =IFERROR(IF(G8/G$6=0,0,G8/G$6),0) -> 0 | H16: =IFERROR(IF(H8/H$6=0,0,H8/H$6),0) -> 0 | I16: =IFERROR(IF(I8/I$6=0,0,I8/I$6),0) -> 0 | J16: =IFERROR(IF(J8/J$6=0,0,J8/J$6),0) -> 0 | ... BM16: =IFERROR(IF(BM8/BM$6=0,0,BM8/BM$6),0) -> 0 | BO16: x
B17: ="Percentual (%) "&B9 -> Percentual (%) Revenda - COM ST - Substituído | C17: =IFERROR(IF(C9/C$6=0,0,C9/C$6),0) -> 0 | D17: =IFERROR(IF(D9/D$6=0,0,D9/D$6),0) -> 0 | E17: =IFERROR(IF(E9/E$6=0,0,E9/E$6),0) -> 0 | F17: =IFERROR(IF(F9/F$6=0,0,F9/F$6),0) -> 0 | G17: =IFERROR(IF(G9/G$6=0,0,G9/G$6),0) -> 0 | H17: =IFERROR(IF(H9/H$6=0,0,H9/H$6),0) -> 0 | I17: =IFERROR(IF(I9/I$6=0,0,I9/I$6),0) -> 0 | J17: =IFERROR(IF(J9/J$6=0,0,J9/J$6),0) -> 0 | ... BM17: =IFERROR(IF(BM9/BM$6=0,0,BM9/BM$6),0) -> 0 | BO17: x
B18: ="Percentual (%) "&B10 -> Percentual (%) Revenda Monofásicos | C18: =IFERROR(IF(C10/C$6=0,0,C10/C$6),0) -> 0 | D18: =IFERROR(IF(D10/D$6=0,0,D10/D$6),0) -> 0 | E18: =IFERROR(IF(E10/E$6=0,0,E10/E$6),0) -> 0 | F18: =IFERROR(IF(F10/F$6=0,0,F10/F$6),0) -> 0 | G18: =IFERROR(IF(G10/G$6=0,0,G10/G$6),0) -> 0 | H18: =IFERROR(IF(H10/H$6=0,0,H10/H$6),0) -> 0 | I18: =IFERROR(IF(I10/I$6=0,0,I10/I$6),0) -> 0 | J18: =IFERROR(IF(J10/J$6=0,0,J10/J$6),0) -> 0 | ... BM18: =IFERROR(IF(BM10/BM$6=0,0,BM10/BM$6),0) -> 0 | BO18: x
B19: ="Percentual (%) "&B11 -> Percentual (%) Revenda Monofásicos + ST | C19: =IFERROR(IF(C11/C$6=0,0,C11/C$6),0) -> 0 | D19: =IFERROR(IF(D11/D$6=0,0,D11/D$6),0) -> 0 | E19: =IFERROR(IF(E11/E$6=0,0,E11/E$6),0) -> 0 | F19: =IFERROR(IF(F11/F$6=0,0,F11/F$6),0) -> 0 | G19: =IFERROR(IF(G11/G$6=0,0,G11/G$6),0) -> 0 | H19: =IFERROR(IF(H11/H$6=0,0,H11/H$6),0) -> 0 | I19: =IFERROR(IF(I11/I$6=0,0,I11/I$6),0) -> 0 | J19: =IFERROR(IF(J11/J$6=0,0,J11/J$6),0) -> 0 | ... BM19: =IFERROR(IF(BM11/BM$6=0,0,BM11/BM$6),0) -> 0 | BO19: x
B20: ="Percentual (%) "&B12 -> Percentual (%) Venda de mercadoria ind. - SEM ST - Substituto | C20: =IFERROR(IF(C12/C$6=0,0,C12/C$6),0) -> 0 | D20: =IFERROR(IF(D12/D$6=0,0,D12/D$6),0) -> 0 | E20: =IFERROR(IF(E12/E$6=0,0,E12/E$6),0) -> 0 | F20: =IFERROR(IF(F12/F$6=0,0,F12/F$6),0) -> 0 | G20: =IFERROR(IF(G12/G$6=0,0,G12/G$6),0) -> 0 | H20: =IFERROR(IF(H12/H$6=0,0,H12/H$6),0) -> 0 | I20: =IFERROR(IF(I12/I$6=0,0,I12/I$6),0) -> 0 | J20: =IFERROR(IF(J12/J$6=0,0,J12/J$6),0) -> 0 | ... BM20: =IFERROR(IF(BM12/BM$6=0,0,BM12/BM$6),0) -> 0 | BO20: x
B21: ="Percentual (%) "&B13 -> Percentual (%) Venda de mercadoria ind. - COM ST - Substituído | C21: =IFERROR(IF(C13/C$6=0,0,C13/C$6),0) -> 0 | D21: =IFERROR(IF(D13/D$6=0,0,D13/D$6),0) -> 0 | E21: =IFERROR(IF(E13/E$6=0,0,E13/E$6),0) -> 0 | F21: =IFERROR(IF(F13/F$6=0,0,F13/F$6),0) -> 0 | G21: =IFERROR(IF(G13/G$6=0,0,G13/G$6),0) -> 0 | H21: =IFERROR(IF(H13/H$6=0,0,H13/H$6),0) -> 0 | I21: =IFERROR(IF(I13/I$6=0,0,I13/I$6),0) -> 0 | J21: =IFERROR(IF(J13/J$6=0,0,J13/J$6),0) -> 0 | ... BM21: =IFERROR(IF(BM13/BM$6=0,0,BM13/BM$6),0) -> 0 | BO21: x
B22: ="Percentual (%) "&B14 -> Percentual (%) Serviço anexo 3 (R$) | C22: =IFERROR(IF(C14/C$6=0,0,C14/C$6),0) -> 0 | D22: =IFERROR(IF(D14/D$6=0,0,D14/D$6),0) -> 0 | E22: =IFERROR(IF(E14/E$6=0,0,E14/E$6),0) -> 0 | F22: =IFERROR(IF(F14/F$6=0,0,F14/F$6),0) -> 0 | G22: =IFERROR(IF(G14/G$6=0,0,G14/G$6),0) -> 0 | H22: =IFERROR(IF(H14/H$6=0,0,H14/H$6),0) -> 0 | I22: =IFERROR(IF(I14/I$6=0,0,I14/I$6),0) -> 0 | J22: =IFERROR(IF(J14/J$6=0,0,J14/J$6),0) -> 0 | ... BM22: =IFERROR(IF(BM14/BM$6=0,0,BM14/BM$6),0) -> 0 | BO22: x
BO23: x
B24: Faixa | C24: =VLOOKUP(C30,'Tabelas SN'!$E$2:$H$7,4,TRUE) -> 1a Faixa | D24: =VLOOKUP(D30,'Tabelas SN'!$E$2:$H$7,4,TRUE) -> 1a Faixa | E24: =VLOOKUP(E30,'Tabelas SN'!$E$2:$H$7,4,TRUE) -> 1a Faixa | F24: =VLOOKUP(F30,'Tabelas SN'!$E$2:$H$7,4,TRUE) -> 1a Faixa | G24: =VLOOKUP(G30,'Tabelas SN'!$E$2:$H$7,4,TRUE) -> 1a Faixa | H24: =VLOOKUP(H30,'Tabelas SN'!$E$2:$H$7,4,TRUE) -> 1a Faixa | I24: =VLOOKUP(I30,'Tabelas SN'!$E$2:$H$7,4,TRUE) -> 1a Faixa | J24: =VLOOKUP(J30,'Tabelas SN'!$E$2:$H$7,4,TRUE) -> 1a Faixa | ... BM24: =VLOOKUP(BM30,'Tabelas SN'!$E$2:$H$7,4,TRUE) -> 1a Faixa | BO24: x
C25: =IF(C6="","",IF(C6=SUM(C7,C8,C9,C10,C11,C12,C13,C14),"ok","erro")) | D25: =IF(D6="","",IF(D6=SUM(D7,D8,D9,D10,D11,D12,D13,D14),"ok","erro")) | E25: =IF(E6="","",IF(E6=SUM(E7,E8,E9,E10,E11,E12,E13,E14),"ok","erro")) | F25: =IF(F6="","",IF(F6=SUM(F7,F8,F9,F10,F11,F12,F13,F14),"ok","erro")) | G25: =IF(G6="","",IF(G6=SUM(G7,G8,G9,G10,G11,G12,G13,G14),"ok","erro")) | H25: =IF(H6="","",IF(H6=SUM(H7,H8,H9,H10,H11,H12,H13,H14),"ok","erro")) | I25: =IF(I6="","",IF(I6=SUM(I7,I8,I9,I10,I11,I12,I13,I14),"ok","erro")) | J25: =IF(J6="","",IF(J6=SUM(J7,J8,J9,J10,J11,J12,J13,J14),"ok","erro")) | ... BM25: =IF(BM6="","",IF(BM6=SUM(BM7,BM8,BM9,BM10,BM11,BM12,BM13,BM14),"ok","erro")) -> ok | BO25: x | BP25: =IF(BP6="","",IF(BP6=SUM(BP7,BP15,BP9,BP10,BP11,BP12,BP14),"ok","erro"))
B26: Receita Acumulada | BO26: x
B27: RBT12 | BB27: =SUM(AP6:BA6) -> 0 | BC27: =SUM(AQ6:BB6) -> 0 | BD27: =SUM(AR6:BC6) -> 0 | BE27: =SUM(AS6:BD6) -> 0 | BF27: =SUM(AT6:BE6) -> 0 | BG27: =SUM(AU6:BF6) -> 0 | BH27: =SUM(AV6:BG6) -> 0 | BI27: =SUM(AW6:BH6) -> 0 | ... BM27: =SUM(BA6:BL6) -> 0 | BO27: x
B28: RBT12p | BO28: x
B29: RBT12simulado | C29: =IFERROR((SUM(OFFSET($B$6,,#REF!-#REF!,1,-#REF!+#REF!)) / (#REF!-#REF!) ) *12,0) -> 0 | D29: =IFERROR((SUM(OFFSET($B$6,,#REF!-#REF!,1,-#REF!+#REF!)) / (#REF!-#REF!) ) *12,0) -> 0 | E29: =IFERROR((SUM(OFFSET($B$6,,#REF!-#REF!,1,-#REF!+#REF!)) / (#REF!-#REF!) ) *12,0) -> 0 | F29: =IFERROR((SUM(OFFSET($B$6,,#REF!-#REF!,1,-#REF!+#REF!)) / (#REF!-#REF!) ) *12,0) -> 0 | G29: =IFERROR((SUM(OFFSET($B$6,,#REF!-#REF!,1,-#REF!+#REF!)) / (#REF!-#REF!) ) *12,0) -> 0 | H29: =IFERROR((SUM(OFFSET($B$6,,#REF!-#REF!,1,-#REF!+#REF!)) / (#REF!-#REF!) ) *12,0) -> 0 | I29: =IFERROR((SUM(OFFSET($B$6,,#REF!-#REF!,1,-#REF!+#REF!)) / (#REF!-#REF!) ) *12,0) -> 0 | J29: =IFERROR((SUM(OFFSET($B$6,,#REF!-#REF!,1,-#REF!+#REF!)) / (#REF!-#REF!) ) *12,0) -> 0 | ... BM29: =IFERROR((SUM(OFFSET($B$6,,#REF!-#REF!,1,-#REF!+#REF!)) / (#REF!-#REF!) ) *12,0) -> 0 | BO29: x
B30: RBT12 Final | C30: =IFERROR(MAX(C27:C28),0) -> 0 | D30: =IFERROR(MAX(D27:D28),0) -> 0 | E30: =IFERROR(MAX(E27:E28),0) -> 0 | F30: =IFERROR(MAX(F27:F28),0) -> 0 | G30: =IFERROR(MAX(G27:G28),0) -> 0 | H30: =IFERROR(MAX(H27:H28),0) -> 0 | I30: =IFERROR(MAX(I27:I28),0) -> 0 | J30: =IFERROR(MAX(J27:J28),0) -> 0 | ... BM30: =IFERROR(MAX(BM27:BM28),0) -> 0 | BO30: x
B31: Total DAS | BO31: x
B32: DAS | BB32: =BB37 -> 0 | BC32: =BC37 -> 0 | BD32: =BD37 -> 0 | BE32: =BE37 -> 0 | BF32: =BF37 -> 0 | BG32: =BG37 -> 0 | BH32: =BH37 -> 0 | BI32: =BI37 -> 0 | ... BM32: =BM37 -> 0 | BO32: x
B33: Percentual (%) | C33: =IFERROR(C32/C6,"-") -> - | D33: =IFERROR(D32/D6,"-") -> - | E33: =IFERROR(E32/E6,"-") -> - | F33: =IFERROR(F32/F6,"-") -> - | G33: =IFERROR(G32/G6,"-") -> - | H33: =IFERROR(H32/H6,"-") -> - | I33: =IFERROR(I32/I6,"-") -> - | J33: =IFERROR(J32/J6,"-") -> - | ... BM33: =IFERROR(BM32/BM6,"-") -> - | BO33: x
BO34: x
A35: x | B35: Cálculo dos Tributos | BO35: x
BO36: x
B37: DAS Calculado | C37: =SUM(C43,C41,C45,C52,C47,C53,) -> 0 | D37: =SUM(D43,D41,D45,D52,D47,D53,) -> 0 | E37: =SUM(E43,E41,E45,E52,E47,E53,) -> 0 | F37: =SUM(F43,F41,F45,F52,F47,F53,) -> 0 | G37: =SUM(G43,G41,G45,G52,G47,G53,) -> 0 | H37: =SUM(H43,H41,H45,H52,H47,H53,) -> 0 | I37: =SUM(I43,I41,I45,I52,I47,I53,) -> 0 | J37: =SUM(J43,J41,J45,J52,J47,J53,) -> 0 | ... BM37: =SUM(BM43,BM41,BM45,BM52,BM47,BM53,) -> 0 | BO37: x
B38: Aliq. Faixa - Anexo 1 | C38: =VLOOKUP(C24,'Tabelas SN'!$A$2:$D$7,3,FALSE) -> 0.04 | D38: =VLOOKUP(D24,'Tabelas SN'!$A$2:$D$7,3,FALSE) -> 0.04 | E38: =VLOOKUP(E24,'Tabelas SN'!$A$2:$D$7,3,FALSE) -> 0.04 | F38: =VLOOKUP(F24,'Tabelas SN'!$A$2:$D$7,3,FALSE) -> 0.04 | G38: =VLOOKUP(G24,'Tabelas SN'!$A$2:$D$7,3,FALSE) -> 0.04 | H38: =VLOOKUP(H24,'Tabelas SN'!$A$2:$D$7,3,FALSE) -> 0.04 | I38: =VLOOKUP(I24,'Tabelas SN'!$A$2:$D$7,3,FALSE) -> 0.04 | J38: =VLOOKUP(J24,'Tabelas SN'!$A$2:$D$7,3,FALSE) -> 0.04 | ... BM38: =VLOOKUP(BM24,'Tabelas SN'!$A$2:$D$7,3,FALSE) -> 0.04 | BO38: x
B39: Imposto para aliq. Efet. | C39: =C38*C30-VLOOKUP(C24,'Tabelas SN'!$A$2:$D$7,4,FALSE) -> 0 | D39: =D38*D30-VLOOKUP(D24,'Tabelas SN'!$A$2:$D$7,4,FALSE) -> 0 | E39: =E38*E30-VLOOKUP(E24,'Tabelas SN'!$A$2:$D$7,4,FALSE) -> 0 | F39: =F38*F30-VLOOKUP(F24,'Tabelas SN'!$A$2:$D$7,4,FALSE) -> 0 | G39: =G38*G30-VLOOKUP(G24,'Tabelas SN'!$A$2:$D$7,4,FALSE) -> 0 | H39: =H38*H30-VLOOKUP(H24,'Tabelas SN'!$A$2:$D$7,4,FALSE) -> 0 | I39: =I38*I30-VLOOKUP(I24,'Tabelas SN'!$A$2:$D$7,4,FALSE) -> 0 | J39: =J38*J30-VLOOKUP(J24,'Tabelas SN'!$A$2:$D$7,4,FALSE) -> 0 | ... BM39: =BM38*BM30-VLOOKUP(BM24,'Tabelas SN'!$A$2:$D$7,4,FALSE) -> 0 | BO39: x
B40: Aliq. Efet. | C40: =IFERROR(C39/C$30,"-") -> - | D40: =IFERROR(D39/D$30,"-") -> - | E40: =IFERROR(E39/E$30,"-") -> - | F40: =IFERROR(F39/F$30,"-") -> - | G40: =IFERROR(G39/G$30,"-") -> - | H40: =IFERROR(H39/H$30,"-") -> - | I40: =IFERROR(I39/I$30,"-") -> - | J40: =IFERROR(J39/J$30,"-") -> - | ... BM40: =IFERROR(BM39/BM$30,"-") -> - | BO40: x
...

Sheet Tabelas SN
A1: Receita Bruta em 12 Meses (em R$) | C1: Alíquota | D1: Valor a Deduzir (em R$) | E1: Min | F1: Max
A2: 1a Faixa | B2: Até 180.000,00 | C2: 0.04 | D2: 0 | E2: 0 | F2: 180000 | G2: =C2 -> 0.04 | H2: =A2 -> 1a Faixa
A3: 2a Faixa | B3: De 180.000,01 a 360.000,00 | C3: 0.073 | D3: 5940 | E3: =F2+0.01 -> 180000.01 | F3: 360000 | G3: =C3 -> 0.073 | H3: =A3 -> 2a Faixa
A4: 3a Faixa | B4: De 360.000,01 a 720.000,00 | C4: 0.095 | D4: 13860 | E4: =F3+0.01 -> 360000.01 | F4: =F3*2 -> 720000 | G4: =C4 -> 0.095 | H4: =A4 -> 3a Faixa
A5: 4a Faixa | B5: De 720.000,01 a 1.800.000,00 | C5: 0.107 | D5: 22500 | E5: =F4+0.01 -> 720000.01 | F5: 1800000 | G5: =C5 -> 0.107 | H5: =A5 -> 4a Faixa
A6: 5a Faixa | B6: De 1.800.000,01 a 3.600.000,00 | C6: 0.143 | D6: 87300 | E6: =F5+0.01 -> 1800000 | F6: =F5*2 -> 3600000 | G6: =C6 -> 0.143 | H6: =A6 -> 5a Faixa
A7: 6a Faixa | B7: De 3.600.000,01 a 4.800.000,00 | C7: 0.19 | D7: 378000 | E7: =F6+0.01 -> 3600000 | F7: 4800000 | G7: =C7 -> 0.19 | H7: =A7 -> 6a Faixa
A9: Faixas | B9: Percentual de Repartição dos Tributos
B10: IRPJ | C10: CSLL | D10: Cofins | E10: PIS/Pasep | F10: CPP | G10: ICMS | H10: ST | I10: Mono | J10: Mono + ST
A11: 1a Faixa | B11: 0.055 | C11: 0.035 | D11: 0.1274 | E11: 0.0276 | F11: 0.415 | G11: 0.34 | H11: =SUM(B11:F11) -> 0.66 | I11: =SUM(B11:G11)-SUM(D11:E11) -> 0.845 | J11: =SUM(B11:C11,F11) -> 0.505
A12: 2a Faixa | B12: 0.055 | C12: 0.035 | D12: 0.1274 | E12: 0.0276 | F12: 0.415 | G12: 0.34 | H12: =SUM(B12:F12) -> 0.66 | I12: =SUM(B12:G12)-SUM(D12:E12) -> 0.845 | J12: =SUM(B12:C12,F12) -> 0.505
A13: 3a Faixa | B13: 0.055 | C13: 0.035 | D13: 0.1274 | E13: 0.0276 | F13: 0.42 | G13: 0.335 | H13: =SUM(B13:F13) -> 0.665 | I13: =SUM(B13:G13)-SUM(D13:E13) -> 0.845 | J13: =SUM(B13:C13,F13) -> 0.51
A14: 4a Faixa | B14: 0.055 | C14: 0.035 | D14: 0.1274 | E14: 0.0276 | F14: 0.42 | G14: 0.335 | H14: =SUM(B14:F14) -> 0.665 | I14: =SUM(B14:G14)-SUM(D14:E14) -> 0.845 | J14: =SUM(B14:C14,F14) -> 0.51
A15: 5a Faixa | B15: 0.055 | C15: 0.035 | D15: 0.1274 | E15: 0.0276 | F15: 0.42 | G15: 0.335 | H15: =SUM(B15:F15) -> 0.665 | I15: =SUM(B15:G15)-SUM(D15:E15) -> 0.845 | J15: =SUM(B15:C15,F15) -> 0.51
A16: 6a Faixa | B16: 0.135 | C16: 0.1 | D16: 0.2827 | E16: 0.0613 | F16: 0.421 | G16: - | H16: =SUM(B16:F16) -> 1 | I16: =SUM(B16:G16)-SUM(D16:E16) -> 0.656 | J16: =SUM(B16:C16,F16) -> 0.656
A19: Alíquota efetiva = RBT12 * Alíquota Nominal – valor à deduzir /RBT12 | I19: =1-SUM(D15:E15) -> 0.845
A21: DAS = Elíquota efetiva * Faturamento
A24: Até R$ 180.000,00 | B24: 0.045 | C24: 0
A25: De R$ 180.000,01 a R$ 360.000,00 | B25: 0.078 | C25: 5940
A26: De R$ 360.000,01 a R$ 720.000,00 | B26: 0.1 | C26: 13860
A27: De R$ 720.000,01 a R$ 1.800.000,00 | B27: 0.112 | C27: 22500
A28: De R$ 1.800.000,01 a R$ R$ 3.600.000,00 | B28: 0.147 | C28: 85500
A29: De R$ 3.600.000,01 a R$ 4.800.000,00 | B29: 0.3 | C29: 720000
A31: Receita Bruta em 12 Meses (em R$) | C31: Alíquota | D31: Valor a Deduzir (em R$) | E31: Min | F31: Max
A32: 1a Faixa | B32: Até 180.000,00 | C32: 0.045 | D32: – | E32: 0 | F32: 180000 | G32: =C32 -> 0.045 | H32: =A32 -> 1a Faixa
A33: 2a Faixa | B33: De 180.000,01 a 360.000,00 | C33: 0.078 | D33: 5940 | E33: =F32+0.01 -> 180000.01 | F33: 360000 | G33: =C33 -> 0.078 | H33: =A33 -> 2a Faixa
A34: 3a Faixa | B34: De 360.000,01 a 720.000,00 | C34: 0.1 | D34: 13860 | E34: =F33+0.01 -> 360000.01 | F34: =F33*2 -> 720000 | G34: =C34 -> 0.1 | H34: =A34 -> 3a Faixa
A35: 4a Faixa | B35: De 720.000,01 a 1.800.000,00 | C35: 0.112 | D35: 22500 | E35: =F34+0.01 -> 720000.01 | F35: 1800000 | G35: =C35 -> 0.112 | H35: =A35 -> 4a Faixa
A36: 5a Faixa | B36: De 1.800.000,01 a 3.600.000,00 | C36: 0.147 | D36: 85500 | E36: =F35+0.01 -> 1800000 | F36: =F35*2 -> 3600000 | G36: =C36 -> 0.147 | H36: =A36 -> 5a Faixa
A37: 6a Faixa | B37: De 3.600.000,01 a 4.800.000,00 | C37: 0.3 | D37: 720000 | E37: =F36+0.01 -> 3600000 | F37: 4800000 | G37: =C37 -> 0.3 | H37: =A37 -> 6a Faixa
A40: CPP | B40: IPI | C40: CSLL | D40: ICMS | E40: IRPJ | F40: Cofins | G40: Faixas | H40: PIS/Pasep
A41: 0.375 | B41: 0.075 | C41: 0.035 | D41: 0.32 | E41: 0.055 | F41: 0.1151 | G41: 1a Faixa | H41: 0.0249
A42: 0.375 | B42: 0.075 | C42: 0.035 | D42: 0.32 | E42: 0.055 | F42: 0.1151 | G42: 2a Faixa | H42: 0.0249
A43: 0.375 | B43: 0.075 | C43: 0.035 | D43: 0.32 | E43: 0.055 | F43: 0.1151 | G43: 3a Faixa | H43: 0.0249
A44: 0.375 | B44: 0.075 | C44: 0.035 | D44: 0.32 | E44: 0.055 | F44: 0.1151 | G44: 4a Faixa | H44: 0.0249
A45: 0.375 | B45: 0.075 | C45: 0.035 | D45: 0.32 | E45: 0.055 | F45: 0.1151 | G45: 5a Faixa | H45: 0.0249
A46: 0.235 | B46: 0.35 | C46: 0.075 | D46: – | E46: 0.085 | F46: 0.2096 | G46: 6a Faixa | H46: 0.0454
A48: Faixas | B48: Percentual de Repartição dos Tributos
B49: IRPJ | C49: CSLL | D49: Cofins | E49: PIS/Pasep | F49: CPP | G49: ICMS | H49: IPI | J49: S/ IPI
A50: 1a Faixa | B50: 0.055 | C50: 0.035 | D50: 0.1151 | E50: 0.0249 | F50: 0.375 | G50: 0.32 | H50: 0.075 | I50: =SUM(B50:H50) -> 1 | J50: =SUM(B50:G50) -> 0.925
...
